<?xml version="1.0"?>
<robot xmlns:xacro="http://www.ros.org/wiki/xacro">

   <xacro:property name="yaml_param_file" value="$(find mirte_base_control)/config/control_master.yaml"/>
    <xacro:property name="params" value="${xacro.load_yaml(yaml_param_file)}"/>

<xacro:arg name="prefix" default="" />


<xacro:macro name="wheel" params="name prefix">

    <joint name="${prefix}${name}_wheel_joint" type="continuous">
      <parent link="${prefix}base_link"/>
      <child link="${prefix}${name}_wheel"/>
      <origin xyz="0 0 0" rpy="0 0 0"/>
      <axis xyz="0 1 0"/>
      <dynamics damping="0.2"/>
    </joint>

    <!-- left wheel Link -->
    <link name="${prefix}${name}_wheel">
</link>
</xacro:macro>

<xacro:macro name="joint" params="name prefix">
      <joint name="${prefix}${name}_wheel_joint">
        <command_interface name="velocity"/>
        <state_interface name="position"/>
        <state_interface name="velocity"/>
      </joint>
</xacro:macro>


   <ros2_control name="mecanumdrive" type="system">
      <hardware>
        <plugin>mirte_base_control/MirteBaseHWInterface</plugin>
        <param name="ticks">${params['ticks']}</param>
        <param name="enable_pid">${params['enable_pid']}</param>
        <param name="kp">${params['kp']}</param>
        <param name="ki">${params['ki']}</param>
        <param name="kd">${params['kd']}</param>
        <param name="i_clamp">${params['i_clamp']}</param>
        <param name="antiwindup">${params['antiwindup']}</param>
      </hardware>

      <xacro:joint prefix="$(arg prefix)" name="front_left"  />
        <xacro:joint prefix="$(arg prefix)" name="front_right"  />
        <xacro:joint prefix="$(arg prefix)" name="rear_right"  />
        <xacro:joint prefix="$(arg prefix)" name="rear_left"  />


    </ros2_control>





<ros2_control name="ros2_arm_control" type="system">
      <hardware>
        <plugin>mirte_master_arm_control/MirteMasterArmHWInterface</plugin>
      </hardware>

   <joint name="shoulder_pan_joint">
        <command_interface name="position"/>
        <state_interface name="position"/>
        <state_interface name="velocity" />
   </joint>

    <joint name="shoulder_lift_joint">
        <command_interface name="position"/>
        <state_interface name="position">
          <param name="initial_value">-1.56</param>
        </state_interface>
        <state_interface name="velocity" />
    </joint>

    <joint name="elbow_joint">
        <command_interface name="position"/>
        <state_interface name="position">
          <param name="initial_value">-1.56</param>
        </state_interface>
        <state_interface name="velocity" />
    </joint>

    <joint name="wrist_joint">
        <command_interface name="position"/>
        <state_interface name="position">
          <param name="initial_value">1.56</param>
        </state_interface>
        <state_interface name="velocity" />
    </joint>
</ros2_control>


<ros2_control name="ros2_gripper_control" type="system">
     <hardware>
        <plugin>mirte_master_arm_control/MirteMasterArmHWInterface</plugin>
      </hardware>

    <joint name="gripper_joint">
        <command_interface name="position"/>
        <state_interface name="position" />
        <state_interface name="velocity" />
    </joint>

<!-- These are only needed in the simulation! -->

<!--
    <joint name="_Gripper_joint_r">
        <param name="mimic">Gripper_joint</param>
        <param name="multiplier">-1</param>
        <command_interface name="position"/>
        <state_interface name="position" />
        <state_interface name="velocity" />
    </joint>

    <joint name="_gripper_link_joint_l">
        <param name="mimic">Gripper_joint</param>
        <param name="multiplier">-1.4</param> 
        <command_interface name="position"/>
        <state_interface name="position" />
        <state_interface name="velocity" />
    </joint>

    <joint name="_gripper_link_joint_r">
        <param name="mimic">Gripper_joint</param>
        <param name="multiplier">1.4</param>  
        <command_interface name="position"/>
        <state_interface name="position" />
        <state_interface name="velocity" />
    </joint>

    <joint name="gripper_finger_joint_l">
        <command_interface name="position"/>
        <state_interface name="position" />
        <state_interface name="velocity" />
    </joint>

    <joint name="gripper_finger_joint_r">
        <command_interface name="position"/>
        <state_interface name="position" />
        <state_interface name="velocity" />
    </joint>
-->

</ros2_control>

<gazebo>
    <plugin filename="libgazebo_ros2_control.so" name="gazebo_ros2_control">
       <parameters>$(find mirte_master_description)/config/mirte_base_control.yaml</parameters>
       <xacro:if value="$(arg arm_enable)">
          <parameters>$(find mirte_master_description)/config/mirte_arm_control.yaml</parameters>
       </xacro:if>
    </plugin>
    <plugin filename="libgazebo_ros_planar_move.so" name="gazebo_planar_move">
       <robot_base_frame>base_link</robot_base_frame> 
    </plugin>
    <plugin name="libgazebo_ros_p3d" filename="libgazebo_ros_p3d.so">
        <ros>
            <namespace>groundtruth</namespace>
            <remapping>odom:=odom</remapping>
        </ros> 
        <frame_name>world</frame_name>
        <body_name>base_link</body_name>
        <update_rate>200.0</update_rate>
        <gaussian_noise>0.0</gaussian_noise>
     </plugin>

</gazebo>

</robot>
