<?xml version="1.0"?>
<!-- Copied from github:ArendJan/mirte-gazebo branch rsp -->
<!-- Modified to remove the collision and change the minimum distance -->
<robot xmlns:xacro="http://www.ros.org/wiki/xacro">
  <xacro:macro name="mecanum_wheel" params="name *origin link_origin wheel_type">

  <link
    name="wheel_${name}">
    <inertial>
      <origin xyz="0 0 ${link_origin}" />
      <mass value="${wheel_mass}" />
      <inertia
        ixx="${wheel_mass * (3 * (wheel_radius**2) + (wheel_length**2)) / 12}"
        iyy="${wheel_mass * (3 * (wheel_radius**2) + (wheel_length**2)) / 12}"
        izz="${wheel_mass * (wheel_radius **2) / 2}"
        ixy="0" ixz="0" iyz="0" />
    </inertial>
    <visual>
      <geometry>
        <mesh
          filename="package://mirte_master_description/meshes/wheel_${wheel_type}.STL" />
      </geometry>
      <material name="">
        <color rgba="0.79216 0.81961 0.93333 1" />
      </material>
    </visual>
    <collision>
      <origin xyz="0 0 ${link_origin}" />
      <geometry>
        <cylinder radius="${wheel_radius}" length="${wheel_length}" />
      </geometry>
    </collision>
  </link>

  <joint
    name="wheel_${name}_joint"
    type="continuous">
    <xacro:insert_block name="origin"/>
    <parent link="frame_link" />
    <child link="wheel_${name}" />
    <axis xyz="0 0 -1" />
  </joint>

  <transmission name="wheel_${name}_transmission">
    <type>transmission_interface/SimpleTransmission</type>
    <joint name="wheel_${name}_joint">
      <hardwareInterface>hardware_interface/VelocityJointInterface</hardwareInterface>
    </joint>
    <actuator name="wheel_${name}_actuator">
      <mechanicalReduction>1</mechanicalReduction>
    </actuator>
  </transmission>

  </xacro:macro>
</robot>
